# Chapter 3
## 계약에 의한 디자인
컴포넌트는 기능을 숨겨 캡슐화하고 함수를 사용할 고객에게는 API를 노출해야 한다.

컴포넌트의 함수, 클래스, 메소드는 특별한 유의사항에 따라 동작해야 하며, 그렇지 않을 경우 코드가 깨진다.  
반대로 코드를 호출하는 클라이언트는 특정 응답을 기대하며 이것과 다른 경우 함수 호출에 실패하고 결함이 발생한다.

코드가 정상적으로 동작하기 위해 기대하는 것과 호출자가 반환 받기를 기대하는 것은 디자인의 하나가 되어야 하고, 여기서 **계약**이라는 개념이 생긴다.

계약에 의한 디자인
- 관계자가 기대하는 바를 암묵적으로 코드에 삽입하는 대신 양측이 동의하는 계약을 먼저 한 다음, 계약을 어겼을 경우는 명시적으로 왜 계속할 수 없는지 예외를 발생시키라는 것이다.

계약
- 소프트웨어 컴포넌트 간의 통신 중에 반드시 지켜져야 할 규칙을 강제하는 것
- 주로 사전조건과 사후조건을 명시하지만 때로는 불변식과 부작용을 기술한다.

사전조건 (precondition)
- 코드가 실행되기 전에 체크해야 하는 것들
- 함수가 진행되기 전에 처리되어야 하는 모든 조건을 체크
- 런타임 중에 확인할 수 있다.
- e.g. 파라미터의 유효성 검사

사후조건 (postcondition)
- 함수 반환 값의 유효성 검사
- 호출자가 이 컴포넌트에서 기대한 것을 제대로 받았는지 확인하기 위해 수행

불변식 (invariant)
- 함수가 실행되는 동안에 일정하게 유지되는 것
- 함수 로직에 문제가 없는지 확인하기 위한 것
- 문서화 하는 것이 좋음

부작용 (side-effect)
- 코드의 부작용

계약에 의해 디자인하는 이유
- 오류가 발생할 때 쉽게 찾아낼 수 있다.
- 잘못된 가정 하에 코드의 핵심 부분이 실행되는 것을 방지

### 사전조건
- 함수나 메소드가 제대로 동작하기 위해 보장해야 하는 모든 것
- 정적 분석 도구 외에도 함수는 처리할 정보에 대한 적절한 유효성 검사를 해야 함
- 유효성 검사를 어디서 하는가?
    - 클라이언트가 함수를 호출하기 전
        - 관용적인 접근법, 함수가 어떤 값이라도 수용하기 때문
    - 함수가 로직을 실행하기 전
        - 까다로운 접근법
    - 검증 로직을 클라이언트에 두거나 함수 자체에 두어 한쪽에서만 하여 중복하지 않도록 한다.

### 사후조건
- 메소드 또는 함수가 반환된 후의 상태를 강제하는 계약의 일부
- 함수 또는 메소드가 사전조건에 맞는다면 사후조건은 특정 속성이 보존되도록 보장해야 한다.

### 파이썬스러운 계약
- 메소드, 함수 및 클래스에 RuntimeError 예외 또는 ValueError 예외를 발생시키는 제어 메커니즘을 추가한다.
- 문제를 정확하게 특정하기 어렵다면 사용자 정의 예외를 만든다.
- 코드를 가능한 한 격리된 상태로 유지한다.
    - 사전조건, 사후조건에 대한 검사, 핵심 기능에 대한 구현을 구분한다.

### 계약에 의한 디자인 (DbC) - 결론
디자인 원칙의 주된 가치
- 문제가 있는 부분을 효과적으로 식별
- 코드가 견고해진다.
- 프로그램 구조를 명확히 한다.

원칙으로 인한 추가 작업
- 계약 작성
- 계약에 대한 단위 테스트 추가

## 방어적 프로그래밍
- 계약에서 예외를 발생시키고 실패하게 되는 모든 조건을 기술하는 대신 객체, 함수 또는 메소드와 같은 코드의 모든 부분을 유효하지 않은 것으로부터 스스로 보호할 수 있게 하는 것
- 다른 디자인 원칙과 결합된 경우 유용
- 주요 주제
    - 에러 핸들링 프로시저
        - 예상할 수 있는 시나리오의 오류를 처리하는 방법
    - assertion
        - 발생하지 않아야 하는 오류를 처리하는 방법

### 에러 핸들링
- 오류가 발생하기 쉬운 상황에서 사용
    - 데이터 입력 확인
- 주요 목적
    - 예상되는 에러에 대해서 실행을 계속할 수 있을지 아니면 치명적인 오류여서 프로그램을 중단할지를 결정하는 것
- 에러 처리 방법
    - 값 대체
    - 에러 로깅
    - 예외 처리

#### 값 대체
- 잘못된 값을 생성해서 전체가 종료될 위험이 있을 경우 결과 값을 안전한 다른 값으로 대체
- 항상 가능하지 않아서 대체 값이 실제로 안전한 옵션인 경우에 한해 신중하게 선택해야 한다.
- 이 결정을 내리는 것은 견고성과 정확성 간의 트레이드 오프이다.
    - 애플리케이션이 민감하고, 중요한 정보를 다루면 정확성을 선택
- 약간 다른 방향으로 보다 안전한 방법을 택하면 데이터에 기본값을 사용
```python
configuration = {"dbport": 5432}
configuration.get("dbhost", "localhost") # 두 번째 파라미터는 기본 값
```
> 'localhost'

```python
# 환경 변수의 API 
import os
os.getenv("DPORT", 5432)
```
> 5432

두 예제 모두 두 번째 파라미터를 제공하지 않으면 함수에서 정한 기본 값인 None을 반환한다.

오류가 있는 데이터를 유사한 값으로 대체하면 일부 오류를 숨겨버릴 수 있음을 고려해야 한다.

#### 예외 처리
- 에러가 발생하기 쉽다는 가정으로 계속 실행하는 것보다 실행을 멈추는 것이 좋은 경우에 호출자에게 실패했음을 알리는 것
    - 사전조건 검증에 실패한 경우
    - 외부 컴포넌트 중 하나의 문제인 경우
- 예외 메커니즘
    - 예외적인 상황을 명확하게 알려주고 원래의 비즈니스 로직에 따라 흐름을 유지하는 것이 중요
- 예외를 사용하여 시나리오나 비즈니스 로직을 처리하려고 하면 프로그램의 흐름을 읽기 어려워진다.
    - 여기서 go-to 문은 상황만 악화시킨다.
- 예외는 캡슐화를 약화시키기 때문에 신중하게 사용해야 한다.
- 예외가 너무 많이 발생하면 여러 개의 작은 것으로 나눠야 한다.

**올바른 수준의 추상화 단계에서 예외 처리**
- 예외는 오직 한 가지 일을 하는 함수의 한 부분이어야 한다.
- 함수가 처리하는 예외는 캡슐화된 로직과 일치해야 한다.
```python
class DataTransport:
    """다른 례벨에서 예외를 처리하는 객체의 예"""

    retry_threshold: int = 5
    retry_n_times: int = 3

    def __init__(self, connector):
        self._connector = connector
        self.connection = None

    def deliver_event(self, event):
        try:
            self.connect()
            data = event.decode()
            self.send(data)
        except ConnectionError as e:
            logger.info("연결 실패: %s", e)
            raise
        except ValueError as e:
            logger.error("%r 잘못된 데이터 포함: %s", event, e)
            raise
        
    def connect(self):
        for _ in range(self.retry_n_times):
            try:
                self.connection = self._connector.connect()
            except ConnectionError as e:
                logger.info(
                    "%s: 새로운 연결 시도 %is",
                    e,
                    self.retry_threshold,
                )
                time.sleep(self.retry_threshold)
            else:
                return self.connection
        raise ConnectionError(
            f"{self.retry_n_times} 번째 재시도 연결 실패"
        )

    def send(self, data):
        return self.connection.send(data)
```
deliver_event() 메소드가 예외 처리하는 방법에 초점을 맞추어 분석
- ValueError와 ConnectionError는 별로 관계가 없다.
    - 책임을 어떻게 분산해야 하는지에 대한 아이디어
- ConnectionError는 connect 메소드 내에서 처리되어야한다.
    - 행동을 명확하게 분리
- deliver_event 메소드는 다른 메소드나 함수로 분리해야 한다.
```python
def connect_with_retry(connector, retry_n_times, retry_threshold=5):
    """connector의 연결을 맺는다. <retry_n_times>회 재시도.

    연결에 성공하면 connection 객체 반환
    재시도까지 모두 실패하면 ConnectionError 발생

    :param connector: '.connect()' 메소드를 가진 객체
    :param retry_n_times int: 'connector.connect()'를 호출 시도하는 횟수
    :param retry_threshold int: 재시도 사이의 간격
    """

    for _ in range(retry_n_times):
        try:
            retrun connector.connect()
        except ConnectionError as e:
            logger.info(
                "%s: 새로운 연결 시도 %is", e, retry_threshold
            )
            time.sleep(retry_threshold)

    exc = ConnectionError(f"{retry_n_times} 번째 재시도 연결 실패")
    logger.exception(exc)
    raise exc
```
이렇게 되면 원래 deliver_event 메소드에서 이 함수를 호출하면 된다.
```python
class DataTrasport:
    """추상화 수준에 따른 예외 분리를 한 객체의 예제"""

    retry_threshold: int = 5
    retry_n_times: int = 3

    def __init__(self, connector):
        self._connector = connector
        self.connection = None

    def deliver_event(self, event):
        self.connection = connect_with_retry(
            self._connector, self.retry__n_times, self.retry_threshold
        )
        self.send(event)

    def send(self, event):
        try:
            return self.connection.send(event.decode())
        exception ValueError as e:
            logger.error("%r 잘못된 데이터 포함: %s", event, e)
            raise
```

**Traceback 노출 금지**  
- 보안을 위한 고려 사항
- 특정 문제를 나타내는 예외가 있는 경우 문제를 효율적으로 해결할 수 있도록 traceback 정보, 메시지 및 기타 수집 가능한 정보를 로그로 남기는 것이 중요
- 그러나 이런 세부사항은 중요 정보나 지적 재산의 유출이 발생할 위험이 있어 절대 사용자에게 보여서는 안 된다.
- 예외가 전파되도록 하는 경우 중요한 정볼르 공개하지 않도록 주의
- 문제를 알릴 때는 일반적인 메세지를 사용하는 방법도 있다.

**비어있는 except 블록 지양**
- 너무 방어적이어서 아무것도 하지 않은 채로 조용히 지나쳐버려 더 심각한 문제로 이어질 수 있다.
```python
try:
    process_data()
except:
    pass
```
- 이 경우 실패해야만 할 때조차도 결코 실패하지 않는다.
- 에러는 결코 조용히 전달되어서는 안 된다.
- 대안
    - 보다 구체적인 예외를 사용
        - 사용자는 무엇을 기대하는지 알게 되어 유지보수하기 쉽다.
    - except 블록에서 실제 오류 처리를 진행
- 가장 좋은 것은 대안 두 항목을 동시에 적용하는 것

**원본 예외 포함**
- 오류 처리 과정에서 다른 오류를 발생시키고 메세지를 변경할 때는 원래 예외를 포함하는 것이 좋다.
- raise \<e\> from \<original_exception\> 구문을 사용
    - 원본의 traceback이 새로운 exception에 포함되고 원본 예외는 \_\_cause\_\_ 속성으로 설정
```python
class InternalDataError(Exception):
    """업무 도메인 데이터의 예외"""

def process(data_dictionary, record_id):
    try:
        return data_dictionary[record_id]
    except KeyError as e:
        raise InternalDataError("Record not present") from e
```

### 파이썬에서 어설션 사용하기
- assert 문에 사용된 표현식은 불가능한 조건을 의미한다.
    - 이 상태가 되면 소프트웨어에 결함이 있음을 의미
- 에러 핸들링과 다르게 프로그램을 계속하거나 중단해야 할 가능성이 있다.
- 잘못된 시나리오에 도달할 경우 프로그램이 더 큰 피해를 입지 않도록 하는 것
- 어설션은 비즈니스 로직과 섞거나 소프트웨어의 제어 흐름 메커니즘으로 사용해서는 안 된다.
```python
# Bad case
try:
    assert condition.holds(), "조건에 맞지 않음."
except AssertionError:
    alternative_procedure()
```
- 어설션에 실패하면 반드시 프로그램을 종료시켜야 한다.

앞의 예제가 나쁜 이유
- AssertionError를 처리한다. (프로그램 종료 X)
- 어설션 문장이 함수
    - 함수 호출은 부작용을 가질 수 있다.
    - 항상 반복 가능하지는 않다.
    - 디버거를 사용해 해당 라인에서 중지하여 오류 결과를 편리하게 볼 수 없다.
    - 다시 호출한다 해도 잘못된 값이었는지 알 수 없다.
```python
# Good case
# 코드를 줄이고, 유용한 정보를 추가
result = condition.holds()
assert result > 0, "에러 {0}".format(result)
```